<mujocoinclude>
    <body name="ned_left/waist" childclass="niryo_ned" pos="-0.55 0 0">
        <inertial pos="-0.0024 -0.0059 0.0516" mass="0.999" diaginertia="0.002 0.002 0.004"/>
        <geom class="visual" mesh="base_black" material="printed_black"/>
        <geom class="visual" mesh="base_blue" material="printed_blue"/>
        <geom class="visual" mesh="base_metal" material="metal_silver"/>
        <geom class="collision" mesh="collision_base_link"/>
        <body name="ned_left/shoulder_link" pos="0 0 0.1065">
            <inertial pos="-0.0307 0.0058 0.0302" mass="0.475" diaginertia="0.0015 0.0015 0.0015"/>
            <joint name="ned_left/waist" class="waist"/>
            <geom class="visual" mesh="shoulder_black" material="printed_black"/>
            <geom class="visual" mesh="shoulder_blue" material="printed_blue"/>
            <geom class="visual" mesh="shoulder_metal" material="metal_silver"/>
            <geom class="collision" mesh="collision_shoulder_link"/>
            <body name="ned_left/arm_link" pos="0 0 0.065">
                <inertial pos="0.1165 -0.0014 -0.0034" mass="0.513" diaginertia="0.0015 0.0015 0.0015"/>
                <joint name="ned_left/shoulder" class="shoulder"/>
                <geom class="visual" mesh="arm_black" material="printed_black" euler="1.57 0 0"/>
                <geom class="visual" mesh="arm_blue" material="printed_blue" euler="1.57 0 0"/>
                <geom class="visual" mesh="arm_metal" material="metal_silver" euler="1.57 0 0"/>
                <geom class="collision" mesh="collision_arm_link" euler="1.57 0 0"/>
                <body name="ned_left/elbow_link" pos="0.221 0 -0.012">
                    <inertial pos="0.0084 0.0235 0.0014" mass="0.201" diaginertia="0.0015 0.0015 0.0015"/>
                    <joint name="ned_left/elbow" class="elbow" ref="-1.34"/>
                    <geom class="visual" mesh="elbow_black" material="printed_black" euler="1.57 0 0"/>
                    <geom class="visual" mesh="elbow_metal" material="metal_silver" euler="1.57 0 0"/>
                    <geom class="collision" mesh="collision_elbow_link" euler="1.57 0 0"/>
                    <body name="ned_left/forearm_link" pos="0.047 0 0.0325">
                        <inertial pos="-0.0081 -0.0001 0.1074" mass="0.204" diaginertia="0.0015 0.0015 0.0015"/>
                        <joint name="ned_left/forearm_roll" class="forearm_roll"/>
                        <geom class="visual" mesh="forearm_black" material="printed_black" euler="1.57 1.57 0"/>
                        <geom class="visual" mesh="forearm_blue" material="printed_blue" euler="1.57 1.57 0"/>
                        <geom class="visual" mesh="forearm_metal" material="metal_silver" euler="1.57 1.57 0"/>
                        <geom class="collision" mesh="collision_forearm_link" euler="1.57 1.57 0"/>
                        <body name="ned_left/wrist_link" pos="0.188 0 0">
                            <inertial pos="-0.0193 -0.0016 0.0003" mass="0.0404" diaginertia="0.0015 0.0015 0.0015"/>
                            <joint name="ned_left/wrist_angle" class="wrist_angle"/>
                            <geom class="visual" mesh="wrist_black" material="printed_black" euler="1.5707 0 0"/>
                            <geom class="visual" mesh="wrist_metal" material="metal_silver" euler="1.5707 0 0"/>
                            <geom class="collision" mesh="collision_wrist_link" euler="1.5707 0 0"/>
                            <body name="ned_left/camera_link" pos="0 0 0.0145" euler="3.14159 0 1.5707">
                                <geom class="visual" mesh="camera" material="printed_black"/>
                                <geom class="collision" mesh="camera"/>
                                <camera name="left_wrist"
                                    pos="0 0 -0.0225"
                                    xyaxes="1 0 0 0 0 -1"
                                    mode="fixed"
                                    fovy="69"
                                    resolution="640 480"/>
                            </body>
                            <body name="ned_left/hand_link" pos="0.0197 0 0.00925">
                                <inertial pos="-5.84e-10 -1.36e-5 0.0088" mass="0.0149" diaginertia="0.0015 0.0015 0.0015"/>
                                <joint name="ned_left/wrist_rotate" class="wrist_rotate" ref="-1.5708"/>
                                <geom class="visual" mesh="hand_black" material="printed_black" euler="0 1.57 0"/>
                                <geom class="visual" mesh="hand_metal" material="metal_silver" euler="0 1.57 0"/>
                                <geom class="collision" mesh="collision_hand_link" euler="0 1.57 0"/>
                                <body name="ned_left/gripper_link" pos="0.0415 0.007 0.004">
                                    <geom class="visual" mesh="gripper_black" material="printed_black" euler="1.57 0 4.71"/>
                                    <geom class="visual" mesh="gripper_metal" material="metal_silver" euler="1.57 0 4.71"/>
                                    <geom class="collision" mesh="gripper_base" euler="1.57 0 4.71"/>
                                    <site pos="0.06 0 0" size="0.003 0.003 0.03" type="box" name="cali_left_site1" rgba="0 0 1 0"/>
                                    <site pos="0.06 0 0" size="0.003 0.03 0.003" type="box" name="cali_left_site2" rgba="0 0 1 0"/>
                                    <site pos="0.06 0 0" size="0.03 0.003 0.003" type="box" name="cali_left_site3" rgba="0 0 1 0"/>
                                    <body name="ned_left/left_finger_link" pos="0.03 -0.007 0.02">
                                        <joint name="ned_left/left_finger" class="left_finger"/>
                                        <geom class="visual" mesh="jaws_metal" material="metal_silver" euler="1.57 0 4.71"/>
                                        <geom class="visual" mesh="left_jaw_black" material="printed_black" euler="1.57 0 4.71"/>
                                        <geom class="collision" mesh="left_jaw" euler="1.57 0 4.71"/>
                                    </body>
                                    <body name="ned_left/right_finger_link" pos="0.03 -0.007 -0.029">
                                        <joint name="ned_left/right_finger" class="right_finger"/>
                                        <geom class="visual" mesh="jaws_metal" material="metal_silver" euler="1.57 0 4.71"/>
                                        <geom class="visual" mesh="right_jaw_black" material="printed_black" euler="1.57 0 4.71"/>
                                        <geom class="collision" mesh="right_jaw" euler="1.57 0 4.71"/>
                                    </body>
                                </body>
                            </body>
                        </body>
                    </body>
                </body>
            </body>
        </body>
    </body>
</mujocoinclude>